O que está gerando esse erro ao chamar a rota de list-prompt?

INFO:     Uvicorn running on http://127.0.0.1:8000 (Press CTRL+C to quit)
INFO:     Started reloader process [64221] using WatchFiles
INFO:     Started server process [64223]
INFO:     Waiting for application startup.
INFO:     Application startup complete.
INFO:     127.0.0.1:38044 - "GET /api/list-prompt HTTP/1.1" 500 Internal Server Error
ERROR:    Exception in ASGI application
Traceback (most recent call last):
  File "/home/arysanchez/.local/lib/python3.10/site-packages/httpx/_transports/default.py", line 69, in map_httpcore_exceptions
    yield
  File "/home/arysanchez/.local/lib/python3.10/site-packages/httpx/_transports/default.py", line 373, in handle_async_request
    resp = await self._pool.handle_async_request(req)
  File "/home/arysanchez/.local/lib/python3.10/site-packages/httpcore/_async/connection_pool.py", line 167, in handle_async_request
    raise UnsupportedProtocol(
httpcore.UnsupportedProtocol: Request URL is missing an 'http://' or 'https://' protocol.

The above exception was the direct cause of the following exception:

Traceback (most recent call last):
  File "/home/arysanchez/.local/lib/python3.10/site-packages/uvicorn/protocols/http/httptools_impl.py", line 399, in run_asgi
    result = await app(  # type: ignore[func-returns-value]
  File "/home/arysanchez/.local/lib/python3.10/site-packages/uvicorn/middleware/proxy_headers.py", line 70, in __call__
    return await self.app(scope, receive, send)
  File "/home/arysanchez/.local/lib/python3.10/site-packages/fastapi/applications.py", line 1054, in __call__
    await super().__call__(scope, receive, send)
  File "/home/arysanchez/.local/lib/python3.10/site-packages/starlette/applications.py", line 123, in __call__
    await self.middleware_stack(scope, receive, send)
  File "/home/arysanchez/.local/lib/python3.10/site-packages/starlette/middleware/errors.py", line 186, in __call__
    raise exc
  File "/home/arysanchez/.local/lib/python3.10/site-packages/starlette/middleware/errors.py", line 164, in __call__
    await self.app(scope, receive, _send)
  File "/home/arysanchez/.local/lib/python3.10/site-packages/starlette/middleware/cors.py", line 93, in __call__
    await self.simple_response(scope, receive, send, request_headers=headers)
  File "/home/arysanchez/.local/lib/python3.10/site-packages/starlette/middleware/cors.py", line 148, in simple_response
    await self.app(scope, receive, send)
  File "/home/arysanchez/.local/lib/python3.10/site-packages/starlette/middleware/exceptions.py", line 65, in __call__
    await wrap_app_handling_exceptions(self.app, conn)(scope, receive, send)
  File "/home/arysanchez/.local/lib/python3.10/site-packages/starlette/_exception_handler.py", line 64, in wrapped_app
    raise exc
  File "/home/arysanchez/.local/lib/python3.10/site-packages/starlette/_exception_handler.py", line 53, in wrapped_app
    await app(scope, receive, sender)
  File "/home/arysanchez/.local/lib/python3.10/site-packages/starlette/routing.py", line 756, in __call__
    await self.middleware_stack(scope, receive, send)
  File "/home/arysanchez/.local/lib/python3.10/site-packages/starlette/routing.py", line 776, in app
    await route.handle(scope, receive, send)
  File "/home/arysanchez/.local/lib/python3.10/site-packages/starlette/routing.py", line 297, in handle
    await self.app(scope, receive, send)
  File "/home/arysanchez/.local/lib/python3.10/site-packages/starlette/routing.py", line 77, in app
    await wrap_app_handling_exceptions(app, request)(scope, receive, send)
  File "/home/arysanchez/.local/lib/python3.10/site-packages/starlette/_exception_handler.py", line 64, in wrapped_app
    raise exc
  File "/home/arysanchez/.local/lib/python3.10/site-packages/starlette/_exception_handler.py", line 53, in wrapped_app
    await app(scope, receive, sender)
  File "/home/arysanchez/.local/lib/python3.10/site-packages/starlette/routing.py", line 72, in app
    response = await func(request)
  File "/home/arysanchez/.local/lib/python3.10/site-packages/fastapi/routing.py", line 278, in app
    raw_response = await run_endpoint_function(
  File "/home/arysanchez/.local/lib/python3.10/site-packages/fastapi/routing.py", line 191, in run_endpoint_function
    return await dependant.call(**values)
  File "/home/arysanchez/Área de Trabalho/prompt-manager-final/backend/app/apis/prompts.py", line 18, in list_external_prompts
    response = await client.get(f"{EXTERNAL_API_URL}channels-service/v1/prompt-templates", headers=headers)
  File "/home/arysanchez/.local/lib/python3.10/site-packages/httpx/_client.py", line 1801, in get
    return await self.request(
  File "/home/arysanchez/.local/lib/python3.10/site-packages/httpx/_client.py", line 1574, in request
    return await self.send(request, auth=auth, follow_redirects=follow_redirects)
  File "/home/arysanchez/.local/lib/python3.10/site-packages/httpx/_client.py", line 1661, in send
    response = await self._send_handling_auth(
  File "/home/arysanchez/.local/lib/python3.10/site-packages/httpx/_client.py", line 1689, in _send_handling_auth
    response = await self._send_handling_redirects(
  File "/home/arysanchez/.local/lib/python3.10/site-packages/httpx/_client.py", line 1726, in _send_handling_redirects
    response = await self._send_single_request(request)
  File "/home/arysanchez/.local/lib/python3.10/site-packages/httpx/_client.py", line 1763, in _send_single_request
    response = await transport.handle_async_request(request)
  File "/home/arysanchez/.local/lib/python3.10/site-packages/httpx/_transports/default.py", line 372, in handle_async_request
    with map_httpcore_exceptions():
  File "/usr/lib/python3.10/contextlib.py", line 153, in __exit__
    self.gen.throw(typ, value, traceback)
  File "/home/arysanchez/.local/lib/python3.10/site-packages/httpx/_transports/default.py", line 86, in map_httpcore_exceptions
    raise mapped_exc(message) from exc
httpx.UnsupportedProtocol: Request URL is missing an 'http://' or 'https://' protocol.
